Workbook
Name Dyn_Elev: OFFSET(Chart_Data!$C$2, 0, 0, Chart_Data!$P$2, 1)
Name Dyn_Grade: OFFSET(Chart_Data!$D$2, 0, 0, Chart_Data!$P$2, 1)
Name Dyn_Over: OFFSET(Chart_Data!$L$2, 0, 0, Chart_Data!$P$2, 1)
Name Dyn_STA: OFFSET(Chart_Data!$A$2, 0, 0, Chart_Data!$P$2, 1)
Name Dyn_STA_Dropdown: OFFSET(Chart_Data!$A$2, 0, 0, Chart_Data!$P$1, 1)
Name Dyn_Warn: OFFSET(Chart_Data!$K$2, 0, 0, Chart_Data!$P$2, 1)

Sheet Data_Monitoring
A1: Nama Jalan | B1: STA | C1: Jarak Kumulatif (m) | D1: Kelas Jalan | E1: Lebar Standar (m) | F1: Lebar Kiri (m) | G1: Lebar Kanan (m) | H1: Lebar Total (m) | I1: Status Lebar Jalan | J1: Elevasi As (m) | K1: Grade Longitudinal (%) | L1: Status Grade | M1: Label Grade (%) | N1: Keterangan Grade | O1: Crossfall Kiri (%) | P1: Status Crossfall Kiri | Q1: Crossfall Kanan (%) | R1: Status Crossfall Kanan | S1: Is_Regular_STA
A2: Jl Bontang | B2: 0+000 | C2: 0 | D2: Class 200 | E2: 30.8 | F2: 16.01 | G2: 14.26 | H2: 30.27 | I2: Nonstandard | J2: 101.04 | L2: N/A | N2: N/A | O2: -1.49 | P2: Nonstandard | Q2: 3.94 | R2: Standard | S2: 1
A3: Jl Bontang | B3: 0+020 | C3: 20 | D3: Class 200 | E3: 30.8 | F3: 18.11 | G3: 13.76 | H3: 31.87 | I3: Standard | J3: 100.68 | K3: -1.78 | L3: Aman | M3: 0.0178 | N3: Flat | O3: -4.21 | P3: Nonstandard | Q3: 4.28 | R3: Nonstandard | S3: 1
A4: Jl Bontang | B4: 0+040 | C4: 40 | D4: Class 200 | E4: 30.8 | F4: 16.22 | G4: 15.83 | H4: 32.05 | I4: Standard | J4: 100.53 | K4: -0.76 | L4: Aman | M4: 0.0076 | N4: Flat | O4: -1.82 | P4: Nonstandard | Q4: 3.59 | R4: Standard | S4: 1
A5: Jl Bontang | B5: 0+060 | C5: 60 | D5: Class 200 | E5: 30.8 | F5: 16.22 | G5: 20 | H5: 36.22 | I5: Standard | J5: 100.99 | K5: 2.28 | L5: Aman | M5: 0.0228 | N5: Tanjakan/Turunan | O5: 2.58 | P5: Standard | Q5: 4.19 | R5: Nonstandard | S5: 1
A6: Jl Bontang | B6: 0+080 | C6: 80 | D6: Class 200 | E6: 30.8 | F6: 15.12 | G6: 20 | H6: 35.12 | I6: Standard | J6: 100.22 | K6: -3.83 | L6: Aman | M6: 0.0383 | N6: Tanjakan/Turunan | O6: -2.78 | P6: Standard | Q6: 5.73 | R6: Nonstandard | S6: 1
A7: Jl Bontang | B7: 0+100 | C7: 100 | D7: Class 200 | E7: 30.8 | F7: 15.63 | G7: 20 | H7: 35.63 | I7: Standard | J7: 99.92 | K7: -1.48 | L7: Aman | M7: 0.0148 | N7: Flat | O7: -4.36 | P7: Nonstandard | Q7: 5.98 | R7: Nonstandard | S7: 1
A8: Jl Bontang | B8: 0+120 | C8: 120 | D8: Class 200 | E8: 30.8 | F8: 16.82 | G8: 20 | H8: 36.82 | I8: Standard | J8: 99.76 | K8: -0.79 | L8: Aman | M8: 0.0079 | N8: Flat | O8: -3.53 | P8: Standard | Q8: 2.42 | R8: Standard | S8: 1
A9: Jl Bontang | B9: 0+140 | C9: 140 | D9: Class 200 | E9: 30.8 | F9: 17.53 | G9: 17.9 | H9: 35.44 | I9: Standard | J9: 99.77 | K9: 0.01 | L9: Aman | M9: 0.0001 | N9: Flat | O9: -4.02 | P9: Nonstandard | Q9: 3.49 | R9: Standard | S9: 1
A10: Jl Bontang | B10: 0+160 | C10: 160 | D10: Class 200 | E10: 30.8 | F10: 17.09 | G10: 16.44 | H10: 33.54 | I10: Standard | J10: 99.84 | K10: 0.37 | L10: Aman | M10: 0.0037 | N10: Flat | O10: -2.71 | P10: Standard | Q10: 2.78 | R10: Standard | S10: 1
A11: Jl Bontang | B11: 0+180 | C11: 180 | D11: Class 200 | E11: 30.8 | F11: 17.04 | G11: 15.47 | H11: 32.51 | I11: Standard | J11: 99.94 | K11: 0.49 | L11: Aman | M11: 0.0049 | N11: Flat | O11: -1.36 | P11: Nonstandard | Q11: 2.74 | R11: Standard | S11: 1
A12: Jl Bontang | B12: 0+200 | C12: 200 | D12: Class 200 | E12: 30.8 | F12: 17 | G12: 15.51 | H12: 32.51 | I12: Standard | J12: 100.21 | K12: 1.38 | L12: Aman | M12: 0.0138 | N12: Flat | O12: 0.01 | P12: Nonstandard | Q12: 3.39 | R12: Standard | S12: 1
A13: Jl Bontang | B13: 0+220 | C13: 220 | D13: Class 200 | E13: 30.8 | F13: 17.33 | G13: 16.97 | H13: 34.3 | I13: Standard | J13: 100.51 | K13: 1.47 | L13: Aman | M13: 0.0147 | N13: Flat | O13: 0.14 | P13: Nonstandard | Q13: 4.67 | R13: Nonstandard | S13: 1
A14: Jl Bontang | B14: 0+240 | C14: 240 | D14: Class 200 | E14: 30.8 | F14: 17.14 | G14: 16.97 | H14: 34.12 | I14: Standard | J14: 100.64 | K14: 0.65 | L14: Aman | M14: 0.0065 | N14: Flat | O14: -1.17 | P14: Nonstandard | Q14: 4.21 | R14: Nonstandard | S14: 1
... A53: Jl Bontang | B53: 1+006.9 | C53: 1006.857 | D53: Class 200 | E53: 30.8 | F53: 17.06 | G53: 20 | H53: 37.06 | I53: Standard | J53: 87.2 | K53: -22.12 | L53: Overgrade | M53: 0.2212 | N53: Tanjakan/Turunan | O53: 3.11 | P53: Standard | Q53: 0.53 | R53: Nonstandard | S53: 0
A54: Jl Sangatta | B54: 0+000 | C54: 0 | D54: Class 200 | E54: 30.8 | F54: 20 | G54: 20 | H54: 40 | I54: Standard | J54: 100.75 | L54: N/A | N54: N/A | O54: -2 | P54: Standard | Q54: -2.4 | R54: Standard | S54: 1
A55: Jl Sangatta | B55: 0+020 | C55: 20 | D55: Class 200 | E55: 30.8 | F55: 20 | G55: 20 | H55: 40 | I55: Standard | J55: 98.05 | K55: -13.54 | L55: Overgrade | M55: 0.1354 | N55: Tanjakan/Turunan | O55: 4.15 | P55: Nonstandard | Q55: -3.03 | R55: Standard | S55: 1
A56: Jl Sangatta | B56: 0+040 | C56: 40 | D56: Class 200 | E56: 30.8 | F56: 20 | G56: 16.97 | H56: 36.97 | I56: Standard | J56: 96.68 | K56: -6.84 | L56: Aman | M56: 0.0684 | N56: Tanjakan/Turunan | O56: 2.02 | P56: Standard | Q56: -0.89 | R56: Nonstandard | S56: 1
A57: Jl Sangatta | B57: 0+060 | C57: 60 | D57: Class 200 | E57: 30.8 | F57: 16.54 | G57: 15.69 | H57: 32.23 | I57: Standard | J57: 95.39 | K57: -6.46 | L57: Aman | M57: 0.0646 | N57: Tanjakan/Turunan | O57: 2.08 | P57: Standard | Q57: -11.67 | R57: Nonstandard | S57: 1
A58: Jl Sangatta | B58: 0+080 | C58: 80 | D58: Class 200 | E58: 30.8 | F58: 13.73 | G58: 14.29 | H58: 28.02 | I58: Nonstandard | J58: 94.01 | K58: -6.87 | L58: Aman | M58: 0.0687 | N58: Tanjakan/Turunan | O58: 1.77 | P58: Nonstandard | Q58: 1.34 | R58: Nonstandard | S58: 1
A59: Jl Sangatta | B59: 0+100 | C59: 100 | D59: Class 200 | E59: 30.8 | F59: 11.94 | G59: 15.69 | H59: 27.63 | I59: Nonstandard | J59: 92.6 | K59: -7.08 | L59: Aman | M59: 0.0708 | N59: Tanjakan/Turunan | O59: 4.34 | P59: Nonstandard | Q59: -0.84 | R59: Nonstandard | S59: 1
A60: Jl Sangatta | B60: 0+120 | C60: 120 | D60: Class 200 | E60: 30.8 | F60: 11.67 | G60: 15.35 | H60: 27.02 | I60: Nonstandard | J60: 91.2 | K60: -7.01 | L60: Aman | M60: 0.0701 | N60: Tanjakan/Turunan | O60: 3.75 | P60: Standard | Q60: -1.55 | R60: Nonstandard | S60: 1
A61: Jl Sangatta | B61: 0+140 | C61: 140 | D61: Class 200 | E61: 30.8 | F61: 11.92 | G61: 16.27 | H61: 28.19 | I61: Nonstandard | J61: 90.09 | K61: -5.52 | L61: Aman | M61: 0.0552 | N61: Tanjakan/Turunan | O61: 4.25 | P61: Nonstandard | Q61: -0.74 | R61: Nonstandard | S61: 1
A62: Jl Sangatta | B62: 0+160 | C62: 160 | D62: Class 200 | E62: 30.8 | F62: 14.14 | G62: 16.27 | H62: 30.41 | I62: Nonstandard | J62: 90.38 | K62: 1.42 | L62: Aman | M62: 0.0142 | N62: Flat | O62: 2.23 | P62: Standard | Q62: 1.65 | R62: Nonstandard | S62: 1
A63: Jl Sangatta | B63: 0+180 | C63: 180 | D63: Class 200 | E63: 30.8 | F63: 14.67 | G63: 16.62 | H63: 31.28 | I63: Standard | J63: 87.61 | K63: -13.81 | L63: Overgrade | M63: 0.1381 | N63: Tanjakan/Turunan | O63: 2.59 | P63: Standard | Q63: -3.63 | R63: Standard | S63: 1
A64: Jl Sangatta | B64: 0+200 | C64: 200 | D64: Class 200 | E64: 30.8 | F64: 15.13 | G64: 16.01 | H64: 31.13 | I64: Standard | J64: 86.6 | K64: -5.05 | L64: Aman | M64: 0.0505 | N64: Tanjakan/Turunan | O64: 3.76 | P64: Standard | Q64: -1.75 | R64: Nonstandard | S64: 1
A65: Jl Sangatta | B65: 0+220 | C65: 220 | D65: Class 200 | E65: 30.8 | F65: 15.42 | G65: 16.14 | H65: 31.57 | I65: Standard | J65: 85.57 | K65: -5.18 | L65: Aman | M65: 0.0518 | N65: Tanjakan/Turunan | O65: 3.12 | P65: Standard | Q65: -2.61 | R65: Standard | S65: 1
A66: Jl Sangatta | B66: 0+240 | C66: 240 | D66: Class 200 | E66: 30.8 | F66: 15 | G66: 16.4 | H66: 31.4 | I66: Standard | J66: 84.81 | K66: -3.77 | L66: Aman | M66: 0.0377 | N66: Tanjakan/Turunan | O66: 4.04 | P66: Nonstandard | Q66: -0.34 | R66: Nonstandard | S66: 1
... A119: Jl Sangatta | B119: 1+289.2 | C119: 1289.175 | D119: Class 200 | E119: 30.8 | F119: 20 | G119: 15.27 | H119: 35.27 | I119: Standard | J119: 77.07 | K119: 1.18 | L119: Aman | M119: 0.0118 | N119: Flat | O119: 1.3 | P119: Nonstandard | Q119: 3.51 | R119: Standard | S119: 0
A120: Jl Makassar | B120: 0+000 | C120: 0 | D120: Class 200 | E120: 30.8 | F120: 20 | G120: 20 | H120: 40 | I120: Standard | J120: 84.93 | L120: N/A | N120: N/A | O120: -0.6 | P120: Nonstandard | Q120: 4.96 | R120: Nonstandard | S120: 1
A121: Jl Makassar | B121: 0+020 | C121: 20 | D121: Class 200 | E121: 30.8 | F121: 20 | G121: 20 | H121: 40 | I121: Standard | J121: 84.42 | K121: -2.55 | L121: Aman | M121: 0.0255 | N121: Tanjakan/Turunan | O121: 13.03 | P121: Nonstandard | Q121: 3.27 | R121: Standard | S121: 1
A122: Jl Makassar | B122: 0+040 | C122: 40 | D122: Class 200 | E122: 30.8 | F122: 18.49 | G122: 20 | H122: 38.49 | I122: Standard | J122: 82.03 | K122: -11.93 | L122: Overgrade | M122: 0.1193 | N122: Tanjakan/Turunan | O122: 8.5 | P122: Nonstandard | Q122: 2.86 | R122: Standard | S122: 1
A123: Jl Makassar | B123: 0+060 | C123: 60 | D123: Class 200 | E123: 30.8 | F123: 18.08 | G123: 20 | H123: 38.08 | I123: Standard | J123: 80.84 | K123: -5.98 | L123: Aman | M123: 0.0598 | N123: Tanjakan/Turunan | O123: 8.85 | P123: Nonstandard | Q123: 4.66 | R123: Nonstandard | S123: 1
A124: Jl Makassar | B124: 0+080 | C124: 80 | D124: Class 200 | E124: 30.8 | F124: 17.44 | G124: 16.9 | H124: 34.34 | I124: Standard | J124: 79.09 | K124: -8.72 | L124: Warning | M124: 0.0872 | N124: Tanjakan/Turunan | O124: 7.28 | P124: Nonstandard | Q124: 6.49 | R124: Nonstandard | S124: 1
A125: Jl Makassar | B125: 0+100 | C125: 100 | D125: Class 200 | E125: 30.8 | F125: 18.08 | G125: 15.98 | H125: 34.06 | I125: Standard | J125: 76.95 | K125: -10.73 | L125: Overgrade | M125: 0.1073 | N125: Tanjakan/Turunan | O125: 0.19 | P125: Nonstandard | Q125: 6.29 | R125: Nonstandard | S125: 1
A126: Jl Makassar | B126: 0+120 | C126: 120 | D126: Class 200 | E126: 30.8 | F126: 20 | G126: 16.58 | H126: 36.58 | I126: Standard | J126: 75.82 | K126: -5.65 | L126: Aman | M126: 0.0565 | N126: Tanjakan/Turunan | O126: 0.14 | P126: Nonstandard | Q126: 5.59 | R126: Nonstandard | S126: 1
A127: Jl Makassar | B127: 0+140 | C127: 140 | D127: Class 200 | E127: 30.8 | F127: 20 | G127: 17.05 | H127: 37.05 | I127: Standard | J127: 75.09 | K127: -3.65 | L127: Aman | M127: 0.0365 | N127: Tanjakan/Turunan | O127: 0.3 | P127: Nonstandard | Q127: 4.88 | R127: Nonstandard | S127: 1
A128: Jl Makassar | B128: 0+160 | C128: 160 | D128: Class 200 | E128: 30.8 | F128: 20 | G128: 20 | H128: 40 | I128: Standard | J128: 74.39 | K128: -3.49 | L128: Aman | M128: 0.0349 | N128: Tanjakan/Turunan | O128: 0.71 | P128: Nonstandard | Q128: 2.89 | R128: Standard | S128: 1
A129: Jl Makassar | B129: 0+180 | C129: 180 | D129: Class 200 | E129: 30.8 | F129: 20 | G129: 20 | H129: 40 | I129: Standard | J129: 73.85 | K129: -2.7 | L129: Aman | M129: 0.027 | N129: Tanjakan/Turunan | O129: -1.53 | P129: Nonstandard | Q129: 4.18 | R129: Nonstandard | S129: 1
A130: Jl Makassar | B130: 0+200 | C130: 200 | D130: Class 200 | E130: 30.8 | F130: 20 | G130: 20 | H130: 40 | I130: Standard | J130: 73.56 | K130: -1.47 | L130: Aman | M130: 0.0147 | N130: Flat | O130: -1.14 | P130: Nonstandard | Q130: 5.8 | R130: Nonstandard | S130: 1
...

Sheet CrossSection_3Pts
A1: Key | B1: Nama Jalan | C1: STA | D1: Point | E1: Lebar_m | F1: Elevasi_RL
A2: Jl Bontang_0+000 | B2: Jl Bontang | C2: 0+000 | D2: Tepi Kiri | E2: 0 | F2: 101.25
A3: Jl Bontang_0+000 | B3: Jl Bontang | C3: 0+000 | D3: As Jalan | E3: 16.01 | F3: 101.04
A4: Jl Bontang_0+000 | B4: Jl Bontang | C4: 0+000 | D4: Tepi Kanan | E4: 30.27 | F4: 100.09
A5: Jl Bontang_0+020 | B5: Jl Bontang | C5: 0+020 | D5: Tepi Kiri | E5: 0 | F5: 101.36
A6: Jl Bontang_0+020 | B6: Jl Bontang | C6: 0+020 | D6: As Jalan | E6: 18.11 | F6: 100.68
A7: Jl Bontang_0+020 | B7: Jl Bontang | C7: 0+020 | D7: Tepi Kanan | E7: 31.87 | F7: 100.17
A8: Jl Bontang_0+040 | B8: Jl Bontang | C8: 0+040 | D8: Tepi Kiri | E8: 0 | F8: 100.79
A9: Jl Bontang_0+040 | B9: Jl Bontang | C9: 0+040 | D9: As Jalan | E9: 16.22 | F9: 100.53
A10: Jl Bontang_0+040 | B10: Jl Bontang | C10: 0+040 | D10: Tepi Kanan | E10: 32.05 | F10: 100.03
A11: Jl Bontang_0+060 | B11: Jl Bontang | C11: 0+060 | D11: Tepi Kiri | E11: 0 | F11: 100.62
A12: Jl Bontang_0+060 | B12: Jl Bontang | C12: 0+060 | D12: As Jalan | E12: 16.22 | F12: 100.99
A13: Jl Bontang_0+060 | B13: Jl Bontang | C13: 0+060 | D13: Tepi Kanan | E13: 36.22 | F13: 99.45
... A8737: Jl Metro_1+942.4 | B8737: Jl Metro | C8737: 1+942.4 | D8737: Tepi Kanan | E8737: 27.79 | F8737: 3.61
A8738: _0+000 | C8738: 0+000 | D8738: Tepi Kiri | E8738: 0 | F8738: -32.16
A8739: _0+000 | C8739: 0+000 | D8739: As Jalan | E8739: 20 | F8739: -32.37
A8740: _0+000 | C8740: 0+000 | D8740: Tepi Kanan | E8740: 29 | F8740: -32.17
A8741: _0+020 | C8741: 0+020 | D8741: Tepi Kiri | E8741: 0 | F8741: -31.39
A8742: _0+020 | C8742: 0+020 | D8742: As Jalan | E8742: 20 | F8742: -32.15
A8743: _0+020 | C8743: 0+020 | D8743: Tepi Kanan | E8743: 29 | F8743: -31.97
A8744: _0+024.7 | C8744: 0+024.7 | D8744: Tepi Kiri | E8744: 0 | F8744: -31.25
A8745: _0+024.7 | C8745: 0+024.7 | D8745: As Jalan | E8745: 20 | F8745: -31.84
A8746: _0+024.7 | C8746: 0+024.7 | D8746: Tepi Kanan | E8746: 28.5 | F8746: -31.56
A8747: _0+000 | C8747: 0+000 | D8747: Tepi Kiri | E8747: 0 | F8747: -30.53
A8748: _0+000 | C8748: 0+000 | D8748: As Jalan | E8748: 20 | F8748: -31.88
A8749: _0+000 | C8749: 0+000 | D8749: Tepi Kanan | E8749: 40 | F8749: -32.23
... A8758: _0+052.8 | C8758: 0+052.8 | D8758: Tepi Kanan | E8758: 29.42 | F8758: -30.84

Sheet Daftar_Pilihan
A1: Nama_Jalan
A2: Jl Bontang
A3: Jl Sangatta
A4: Jl Makassar
A5: Jl Banjarmasin Atas
A6: Jl BPP Ambon
A7: Jl Flores New
A8: Jl Binjai
A9: Jl Medan
A10: Jl Bone
A11: Jl Denpasar
A12: Jl Subang
... A37: Jl Metro

Sheet Chart_Data
A1: STA | B1: Jarak_m | C1: Elevasi_m | D1: Grade_pct | E1: Lebar_m | F1: Crossfall_L | G1: Crossfall_R | H1: Status_Grade | I1: Grade_Text | J1: Elev_Aman | K1: Elev_Warning | L1: Elev_Overgrade | M1: Is_Regular | N1: Active_STA | O1: Total_Pts | P1: =COUNTIF(Data_Monitoring!$A$2:$A$2920, Dashboard_Visual!$B$4) -> 52
A2: =IF(1<=COUNTIF(Data_Monitoring!$A$2:$A$2920, Dashboard_Visual!$B$4), INDEX(Data_Monitoring!$B$2:$B$2920, MATCH(Dashboard_Visual!$B$4, Data_Monitoring!$A$2:$A$2920, 0) + 1 - 1), "") -> 0+000 | B2: =IF(1<=COUNTIF(Data_Monitoring!$A$2:$A$2920, Dashboard_Visual!$B$4), INDEX(Data_Monitoring!$C$2:$C$2920, MATCH(Dashboard_Visual!$B$4, Data_Monitoring!$A$2:$A$2920, 0) + 1 - 1), "") -> 0 | C2: =IF(1<=COUNTIF(Data_Monitoring!$A$2:$A$2920, Dashboard_Visual!$B$4), INDEX(Data_Monitoring!$J$2:$J$2920, MATCH(Dashboard_Visual!$B$4, Data_Monitoring!$A$2:$A$2920, 0) + 1 - 1), NA()) -> 101.04 | D2: =IF(1<=COUNTIF(Data_Monitoring!$A$2:$A$2920, Dashboard_Visual!$B$4), INDEX(Data_Monitoring!$K$2:$K$2920, MATCH(Dashboard_Visual!$B$4, Data_Monitoring!$A$2:$A$2920, 0) + 1 - 1), NA()) -> 0 | E2: =IF(1<=COUNTIF(Data_Monitoring!$A$2:$A$2920, Dashboard_Visual!$B$4), INDEX(Data_Monitoring!$H$2:$H$2920, MATCH(Dashboard_Visual!$B$4, Data_Monitoring!$A$2:$A$2920, 0) + 1 - 1), 0) -> 30.27 | F2: =IF(1<=COUNTIF(Data_Monitoring!$A$2:$A$2920, Dashboard_Visual!$B$4), INDEX(Data_Monitoring!$O$2:$O$2920, MATCH(Dashboard_Visual!$B$4, Data_Monitoring!$A$2:$A$2920, 0) + 1 - 1), 0) -> -1.49 | G2: =IF(1<=COUNTIF(Data_Monitoring!$A$2:$A$2920, Dashboard_Visual!$B$4), INDEX(Data_Monitoring!$Q$2:$Q$2920, MATCH(Dashboard_Visual!$B$4, Data_Monitoring!$A$2:$A$2920, 0) + 1 - 1), 0) -> 3.94 | H2: =IF(1<=COUNTIF(Data_Monitoring!$A$2:$A$2920, Dashboard_Visual!$B$4), INDEX(Data_Monitoring!$L$2:$L$2920, MATCH(Dashboard_Visual!$B$4, Data_Monitoring!$A$2:$A$2920, 0) + 1 - 1), "") -> N/A | I2: =IF(AND(1<=$P$2, ISNUMBER(D2), OR(H2="Warning", H2="Overgrade")), TEXT(ABS(D2)/100, "0.00%"), "") | J2: =IF(H2="Aman", C2, NA()) -> #N/A | K2: =IF(AND(1<=$P$2, H2="Warning"), C2, NA()) -> #N/A | L2: =IF(AND(1<=$P$2, H2="Overgrade"), C2, NA()) -> #N/A | M2: =IF(1<=COUNTIF(Data_Monitoring!$A$2:$A$2920, Dashboard_Visual!$B$4), INDEX(Data_Monitoring!$S$2:$S$2920, MATCH(Dashboard_Visual!$B$4, Data_Monitoring!$A$2:$A$2920, 0) + 1 - 1), 1) -> 1 | N2: =IF(ISNUMBER(MATCH(Dashboard_Visual!$B$3, Chart_Data!$A$2:$A$247, 0)), Dashboard_Visual!$B$3, Chart_Data!$A$2) -> 0+040 | O2: Chart_Pts | P2: =P1 - IF(INDEX(M2:M247, P1)=0, 1, 0) -> 51
A3: =IF(2<=COUNTIF(Data_Monitoring!$A$2:$A$2920, Dashboard_Visual!$B$4), INDEX(Data_Monitoring!$B$2:$B$2920, MATCH(Dashboard_Visual!$B$4, Data_Monitoring!$A$2:$A$2920, 0) + 2 - 1), "") -> 0+020 | B3: =IF(2<=COUNTIF(Data_Monitoring!$A$2:$A$2920, Dashboard_Visual!$B$4), INDEX(Data_Monitoring!$C$2:$C$2920, MATCH(Dashboard_Visual!$B$4, Data_Monitoring!$A$2:$A$2920, 0) + 2 - 1), "") -> 20 | C3: =IF(2<=COUNTIF(Data_Monitoring!$A$2:$A$2920, Dashboard_Visual!$B$4), INDEX(Data_Monitoring!$J$2:$J$2920, MATCH(Dashboard_Visual!$B$4, Data_Monitoring!$A$2:$A$2920, 0) + 2 - 1), NA()) -> 100.68 | D3: =IF(2<=COUNTIF(Data_Monitoring!$A$2:$A$2920, Dashboard_Visual!$B$4), INDEX(Data_Monitoring!$K$2:$K$2920, MATCH(Dashboard_Visual!$B$4, Data_Monitoring!$A$2:$A$2920, 0) + 2 - 1), NA()) -> -1.78 | E3: =IF(2<=COUNTIF(Data_Monitoring!$A$2:$A$2920, Dashboard_Visual!$B$4), INDEX(Data_Monitoring!$H$2:$H$2920, MATCH(Dashboard_Visual!$B$4, Data_Monitoring!$A$2:$A$2920, 0) + 2 - 1), 0) -> 31.87 | F3: =IF(2<=COUNTIF(Data_Monitoring!$A$2:$A$2920, Dashboard_Visual!$B$4), INDEX(Data_Monitoring!$O$2:$O$2920, MATCH(Dashboard_Visual!$B$4, Data_Monitoring!$A$2:$A$2920, 0) + 2 - 1), 0) -> -4.21 | G3: =IF(2<=COUNTIF(Data_Monitoring!$A$2:$A$2920, Dashboard_Visual!$B$4), INDEX(Data_Monitoring!$Q$2:$Q$2920, MATCH(Dashboard_Visual!$B$4, Data_Monitoring!$A$2:$A$2920, 0) + 2 - 1), 0) -> 4.28 | H3: =IF(2<=COUNTIF(Data_Monitoring!$A$2:$A$2920, Dashboard_Visual!$B$4), INDEX(Data_Monitoring!$L$2:$L$2920, MATCH(Dashboard_Visual!$B$4, Data_Monitoring!$A$2:$A$2920, 0) + 2 - 1), "") -> Aman | I3: =IF(AND(2<=$P$2, ISNUMBER(D3), OR(H3="Warning", H3="Overgrade")), TEXT(ABS(D3)/100, "0.00%"), "") | J3: =IF(H3="Aman", C3, NA()) -> 100.68 | K3: =IF(AND(2<=$P$2, H3="Warning"), C3, NA()) -> #N/A | L3: =IF(AND(2<=$P$2, H3="Overgrade"), C3, NA()) -> #N/A | M3: =IF(2<=COUNTIF(Data_Monitoring!$A$2:$A$2920, Dashboard_Visual!$B$4), INDEX(Data_Monitoring!$S$2:$S$2920, MATCH(Dashboard_Visual!$B$4, Data_Monitoring!$A$2:$A$2920, 0) + 2 - 1), 1) -> 1
A4: =IF(3<=COUNTIF(Data_Monitoring!$A$2:$A$2920, Dashboard_Visual!$B$4), INDEX(Data_Monitoring!$B$2:$B$2920, MATCH(Dashboard_Visual!$B$4, Data_Monitoring!$A$2:$A$2920, 0) + 3 - 1), "") -> 0+040 | B4: =IF(3<=COUNTIF(Data_Monitoring!$A$2:$A$2920, Dashboard_Visual!$B$4), INDEX(Data_Monitoring!$C$2:$C$2920, MATCH(Dashboard_Visual!$B$4, Data_Monitoring!$A$2:$A$2920, 0) + 3 - 1), "") -> 40 | C4: =IF(3<=COUNTIF(Data_Monitoring!$A$2:$A$2920, Dashboard_Visual!$B$4), INDEX(Data_Monitoring!$J$2:$J$2920, MATCH(Dashboard_Visual!$B$4, Data_Monitoring!$A$2:$A$2920, 0) + 3 - 1), NA()) -> 100.53 | D4: =IF(3<=COUNTIF(Data_Monitoring!$A$2:$A$2920, Dashboard_Visual!$B$4), INDEX(Data_Monitoring!$K$2:$K$2920, MATCH(Dashboard_Visual!$B$4, Data_Monitoring!$A$2:$A$2920, 0) + 3 - 1), NA()) -> -0.76 | E4: =IF(3<=COUNTIF(Data_Monitoring!$A$2:$A$2920, Dashboard_Visual!$B$4), INDEX(Data_Monitoring!$H$2:$H$2920, MATCH(Dashboard_Visual!$B$4, Data_Monitoring!$A$2:$A$2920, 0) + 3 - 1), 0) -> 32.05 | F4: =IF(3<=COUNTIF(Data_Monitoring!$A$2:$A$2920, Dashboard_Visual!$B$4), INDEX(Data_Monitoring!$O$2:$O$2920, MATCH(Dashboard_Visual!$B$4, Data_Monitoring!$A$2:$A$2920, 0) + 3 - 1), 0) -> -1.82 | G4: =IF(3<=COUNTIF(Data_Monitoring!$A$2:$A$2920, Dashboard_Visual!$B$4), INDEX(Data_Monitoring!$Q$2:$Q$2920, MATCH(Dashboard_Visual!$B$4, Data_Monitoring!$A$2:$A$2920, 0) + 3 - 1), 0) -> 3.59 | H4: =IF(3<=COUNTIF(Data_Monitoring!$A$2:$A$2920, Dashboard_Visual!$B$4), INDEX(Data_Monitoring!$L$2:$L$2920, MATCH(Dashboard_Visual!$B$4, Data_Monitoring!$A$2:$A$2920, 0) + 3 - 1), "") -> Aman | I4: =IF(AND(3<=$P$2, ISNUMBER(D4), OR(H4="Warning", H4="Overgrade")), TEXT(ABS(D4)/100, "0.00%"), "") | J4: =IF(H4="Aman", C4, NA()) -> 100.53 | K4: =IF(AND(3<=$P$2, H4="Warning"), C4, NA()) -> #N/A | L4: =IF(AND(3<=$P$2, H4="Overgrade"), C4, NA()) -> #N/A | M4: =IF(3<=COUNTIF(Data_Monitoring!$A$2:$A$2920, Dashboard_Visual!$B$4), INDEX(Data_Monitoring!$S$2:$S$2920, MATCH(Dashboard_Visual!$B$4, Data_Monitoring!$A$2:$A$2920, 0) + 3 - 1), 1) -> 1
A5: =IF(4<=COUNTIF(Data_Monitoring!$A$2:$A$2920, Dashboard_Visual!$B$4), INDEX(Data_Monitoring!$B$2:$B$2920, MATCH(Dashboard_Visual!$B$4, Data_Monitoring!$A$2:$A$2920, 0) + 4 - 1), "") -> 0+060 | B5: =IF(4<=COUNTIF(Data_Monitoring!$A$2:$A$2920, Dashboard_Visual!$B$4), INDEX(Data_Monitoring!$C$2:$C$2920, MATCH(Dashboard_Visual!$B$4, Data_Monitoring!$A$2:$A$2920, 0) + 4 - 1), "") -> 60 | C5: =IF(4<=COUNTIF(Data_Monitoring!$A$2:$A$2920, Dashboard_Visual!$B$4), INDEX(Data_Monitoring!$J$2:$J$2920, MATCH(Dashboard_Visual!$B$4, Data_Monitoring!$A$2:$A$2920, 0) + 4 - 1), NA()) -> 100.99 | D5: =IF(4<=COUNTIF(Data_Monitoring!$A$2:$A$2920, Dashboard_Visual!$B$4), INDEX(Data_Monitoring!$K$2:$K$2920, MATCH(Dashboard_Visual!$B$4, Data_Monitoring!$A$2:$A$2920, 0) + 4 - 1), NA()) -> 2.28 | E5: =IF(4<=COUNTIF(Data_Monitoring!$A$2:$A$2920, Dashboard_Visual!$B$4), INDEX(Data_Monitoring!$H$2:$H$2920, MATCH(Dashboard_Visual!$B$4, Data_Monitoring!$A$2:$A$2920, 0) + 4 - 1), 0) -> 36.22 | F5: =IF(4<=COUNTIF(Data_Monitoring!$A$2:$A$2920, Dashboard_Visual!$B$4), INDEX(Data_Monitoring!$O$2:$O$2920, MATCH(Dashboard_Visual!$B$4, Data_Monitoring!$A$2:$A$2920, 0) + 4 - 1), 0) -> 2.58 | G5: =IF(4<=COUNTIF(Data_Monitoring!$A$2:$A$2920, Dashboard_Visual!$B$4), INDEX(Data_Monitoring!$Q$2:$Q$2920, MATCH(Dashboard_Visual!$B$4, Data_Monitoring!$A$2:$A$2920, 0) + 4 - 1), 0) -> 4.19 | H5: =IF(4<=COUNTIF(Data_Monitoring!$A$2:$A$2920, Dashboard_Visual!$B$4), INDEX(Data_Monitoring!$L$2:$L$2920, MATCH(Dashboard_Visual!$B$4, Data_Monitoring!$A$2:$A$2920, 0) + 4 - 1), "") -> Aman | I5: =IF(AND(4<=$P$2, ISNUMBER(D5), OR(H5="Warning", H5="Overgrade")), TEXT(ABS(D5)/100, "0.00%"), "") | J5: =IF(H5="Aman", C5, NA()) -> 100.99 | K5: =IF(AND(4<=$P$2, H5="Warning"), C5, NA()) -> #N/A | L5: =IF(AND(4<=$P$2, H5="Overgrade"), C5, NA()) -> #N/A | M5: =IF(4<=COUNTIF(Data_Monitoring!$A$2:$A$2920, Dashboard_Visual!$B$4), INDEX(Data_Monitoring!$S$2:$S$2920, MATCH(Dashboard_Visual!$B$4, Data_Monitoring!$A$2:$A$2920, 0) + 4 - 1), 1) -> 1
A6: =IF(5<=COUNTIF(Data_Monitoring!$A$2:$A$2920, Dashboard_Visual!$B$4), INDEX(Data_Monitoring!$B$2:$B$2920, MATCH(Dashboard_Visual!$B$4, Data_Monitoring!$A$2:$A$2920, 0) + 5 - 1), "") -> 0+080 | B6: =IF(5<=COUNTIF(Data_Monitoring!$A$2:$A$2920, Dashboard_Visual!$B$4), INDEX(Data_Monitoring!$C$2:$C$2920, MATCH(Dashboard_Visual!$B$4, Data_Monitoring!$A$2:$A$2920, 0) + 5 - 1), "") -> 80 | C6: =IF(5<=COUNTIF(Data_Monitoring!$A$2:$A$2920, Dashboard_Visual!$B$4), INDEX(Data_Monitoring!$J$2:$J$2920, MATCH(Dashboard_Visual!$B$4, Data_Monitoring!$A$2:$A$2920, 0) + 5 - 1), NA()) -> 100.22 | D6: =IF(5<=COUNTIF(Data_Monitoring!$A$2:$A$2920, Dashboard_Visual!$B$4), INDEX(Data_Monitoring!$K$2:$K$2920, MATCH(Dashboard_Visual!$B$4, Data_Monitoring!$A$2:$A$2920, 0) + 5 - 1), NA()) -> -3.83 | E6: =IF(5<=COUNTIF(Data_Monitoring!$A$2:$A$2920, Dashboard_Visual!$B$4), INDEX(Data_Monitoring!$H$2:$H$2920, MATCH(Dashboard_Visual!$B$4, Data_Monitoring!$A$2:$A$2920, 0) + 5 - 1), 0) -> 35.12 | F6: =IF(5<=COUNTIF(Data_Monitoring!$A$2:$A$2920, Dashboard_Visual!$B$4), INDEX(Data_Monitoring!$O$2:$O$2920, MATCH(Dashboard_Visual!$B$4, Data_Monitoring!$A$2:$A$2920, 0) + 5 - 1), 0) -> -2.78 | G6: =IF(5<=COUNTIF(Data_Monitoring!$A$2:$A$2920, Dashboard_Visual!$B$4), INDEX(Data_Monitoring!$Q$2:$Q$2920, MATCH(Dashboard_Visual!$B$4, Data_Monitoring!$A$2:$A$2920, 0) + 5 - 1), 0) -> 5.73 | H6: =IF(5<=COUNTIF(Data_Monitoring!$A$2:$A$2920, Dashboard_Visual!$B$4), INDEX(Data_Monitoring!$L$2:$L$2920, MATCH(Dashboard_Visual!$B$4, Data_Monitoring!$A$2:$A$2920, 0) + 5 - 1), "") -> Aman | I6: =IF(AND(5<=$P$2, ISNUMBER(D6), OR(H6="Warning", H6="Overgrade")), TEXT(ABS(D6)/100, "0.00%"), "") | J6: =IF(H6="Aman", C6, NA()) -> 100.22 | K6: =IF(AND(5<=$P$2, H6="Warning"), C6, NA()) -> #N/A | L6: =IF(AND(5<=$P$2, H6="Overgrade"), C6, NA()) -> #N/A | M6: =IF(5<=COUNTIF(Data_Monitoring!$A$2:$A$2920, Dashboard_Visual!$B$4), INDEX(Data_Monitoring!$S$2:$S$2920, MATCH(Dashboard_Visual!$B$4, Data_Monitoring!$A$2:$A$2920, 0) + 5 - 1), 1) -> 1
A7: =IF(6<=COUNTIF(Data_Monitoring!$A$2:$A$2920, Dashboard_Visual!$B$4), INDEX(Data_Monitoring!$B$2:$B$2920, MATCH(Dashboard_Visual!$B$4, Data_Monitoring!$A$2:$A$2920, 0) + 6 - 1), "") -> 0+100 | B7: =IF(6<=COUNTIF(Data_Monitoring!$A$2:$A$2920, Dashboard_Visual!$B$4), INDEX(Data_Monitoring!$C$2:$C$2920, MATCH(Dashboard_Visual!$B$4, Data_Monitoring!$A$2:$A$2920, 0) + 6 - 1), "") -> 100 | C7: =IF(6<=COUNTIF(Data_Monitoring!$A$2:$A$2920, Dashboard_Visual!$B$4), INDEX(Data_Monitoring!$J$2:$J$2920, MATCH(Dashboard_Visual!$B$4, Data_Monitoring!$A$2:$A$2920, 0) + 6 - 1), NA()) -> 99.92 | D7: =IF(6<=COUNTIF(Data_Monitoring!$A$2:$A$2920, Dashboard_Visual!$B$4), INDEX(Data_Monitoring!$K$2:$K$2920, MATCH(Dashboard_Visual!$B$4, Data_Monitoring!$A$2:$A$2920, 0) + 6 - 1), NA()) -> -1.48 | E7: =IF(6<=COUNTIF(Data_Monitoring!$A$2:$A$2920, Dashboard_Visual!$B$4), INDEX(Data_Monitoring!$H$2:$H$2920, MATCH(Dashboard_Visual!$B$4, Data_Monitoring!$A$2:$A$2920, 0) + 6 - 1), 0) -> 35.63 | F7: =IF(6<=COUNTIF(Data_Monitoring!$A$2:$A$2920, Dashboard_Visual!$B$4), INDEX(Data_Monitoring!$O$2:$O$2920, MATCH(Dashboard_Visual!$B$4, Data_Monitoring!$A$2:$A$2920, 0) + 6 - 1), 0) -> -4.36 | G7: =IF(6<=COUNTIF(Data_Monitoring!$A$2:$A$2920, Dashboard_Visual!$B$4), INDEX(Data_Monitoring!$Q$2:$Q$2920, MATCH(Dashboard_Visual!$B$4, Data_Monitoring!$A$2:$A$2920, 0) + 6 - 1), 0) -> 5.98 | H7: =IF(6<=COUNTIF(Data_Monitoring!$A$2:$A$2920, Dashboard_Visual!$B$4), INDEX(Data_Monitoring!$L$2:$L$2920, MATCH(Dashboard_Visual!$B$4, Data_Monitoring!$A$2:$A$2920, 0) + 6 - 1), "") -> Aman | I7: =IF(AND(6<=$P$2, ISNUMBER(D7), OR(H7="Warning", H7="Overgrade")), TEXT(ABS(D7)/100, "0.00%"), "") | J7: =IF(H7="Aman", C7, NA()) -> 99.92 | K7: =IF(AND(6<=$P$2, H7="Warning"), C7, NA()) -> #N/A | L7: =IF(AND(6<=$P$2, H7="Overgrade"), C7, NA()) -> #N/A | M7: =IF(6<=COUNTIF(Data_Monitoring!$A$2:$A$2920, Dashboard_Visual!$B$4), INDEX(Data_Monitoring!$S$2:$S$2920, MATCH(Dashboard_Visual!$B$4, Data_Monitoring!$A$2:$A$2920, 0) + 6 - 1), 1) -> 1
A8: =IF(7<=COUNTIF(Data_Monitoring!$A$2:$A$2920, Dashboard_Visual!$B$4), INDEX(Data_Monitoring!$B$2:$B$2920, MATCH(Dashboard_Visual!$B$4, Data_Monitoring!$A$2:$A$2920, 0) + 7 - 1), "") -> 0+120 | B8: =IF(7<=COUNTIF(Data_Monitoring!$A$2:$A$2920, Dashboard_Visual!$B$4), INDEX(Data_Monitoring!$C$2:$C$2920, MATCH(Dashboard_Visual!$B$4, Data_Monitoring!$A$2:$A$2920, 0) + 7 - 1), "") -> 120 | C8: =IF(7<=COUNTIF(Data_Monitoring!$A$2:$A$2920, Dashboard_Visual!$B$4), INDEX(Data_Monitoring!$J$2:$J$2920, MATCH(Dashboard_Visual!$B$4, Data_Monitoring!$A$2:$A$2920, 0) + 7 - 1), NA()) -> 99.76 | D8: =IF(7<=COUNTIF(Data_Monitoring!$A$2:$A$2920, Dashboard_Visual!$B$4), INDEX(Data_Monitoring!$K$2:$K$2920, MATCH(Dashboard_Visual!$B$4, Data_Monitoring!$A$2:$A$2920, 0) + 7 - 1), NA()) -> -0.79 | E8: =IF(7<=COUNTIF(Data_Monitoring!$A$2:$A$2920, Dashboard_Visual!$B$4), INDEX(Data_Monitoring!$H$2:$H$2920, MATCH(Dashboard_Visual!$B$4, Data_Monitoring!$A$2:$A$2920, 0) + 7 - 1), 0) -> 36.82 | F8: =IF(7<=COUNTIF(Data_Monitoring!$A$2:$A$2920, Dashboard_Visual!$B$4), INDEX(Data_Monitoring!$O$2:$O$2920, MATCH(Dashboard_Visual!$B$4, Data_Monitoring!$A$2:$A$2920, 0) + 7 - 1), 0) -> -3.53 | G8: =IF(7<=COUNTIF(Data_Monitoring!$A$2:$A$2920, Dashboard_Visual!$B$4), INDEX(Data_Monitoring!$Q$2:$Q$2920, MATCH(Dashboard_Visual!$B$4, Data_Monitoring!$A$2:$A$2920, 0) + 7 - 1), 0) -> 2.42 | H8: =IF(7<=COUNTIF(Data_Monitoring!$A$2:$A$2920, Dashboard_Visual!$B$4), INDEX(Data_Monitoring!$L$2:$L$2920, MATCH(Dashboard_Visual!$B$4, Data_Monitoring!$A$2:$A$2920, 0) + 7 - 1), "") -> Aman | I8: =IF(AND(7<=$P$2, ISNUMBER(D8), OR(H8="Warning", H8="Overgrade")), TEXT(ABS(D8)/100, "0.00%"), "") | J8: =IF(H8="Aman", C8, NA()) -> 99.76 | K8: =IF(AND(7<=$P$2, H8="Warning"), C8, NA()) -> #N/A | L8: =IF(AND(7<=$P$2, H8="Overgrade"), C8, NA()) -> #N/A | M8: =IF(7<=COUNTIF(Data_Monitoring!$A$2:$A$2920, Dashboard_Visual!$B$4), INDEX(Data_Monitoring!$S$2:$S$2920, MATCH(Dashboard_Visual!$B$4, Data_Monitoring!$A$2:$A$2920, 0) + 7 - 1), 1) -> 1
A9: =IF(8<=COUNTIF(Data_Monitoring!$A$2:$A$2920, Dashboard_Visual!$B$4), INDEX(Data_Monitoring!$B$2:$B$2920, MATCH(Dashboard_Visual!$B$4, Data_Monitoring!$A$2:$A$2920, 0) + 8 - 1), "") -> 0+140 | B9: =IF(8<=COUNTIF(Data_Monitoring!$A$2:$A$2920, Dashboard_Visual!$B$4), INDEX(Data_Monitoring!$C$2:$C$2920, MATCH(Dashboard_Visual!$B$4, Data_Monitoring!$A$2:$A$2920, 0) + 8 - 1), "") -> 140 | C9: =IF(8<=COUNTIF(Data_Monitoring!$A$2:$A$2920, Dashboard_Visual!$B$4), INDEX(Data_Monitoring!$J$2:$J$2920, MATCH(Dashboard_Visual!$B$4, Data_Monitoring!$A$2:$A$2920, 0) + 8 - 1), NA()) -> 99.77 | D9: =IF(8<=COUNTIF(Data_Monitoring!$A$2:$A$2920, Dashboard_Visual!$B$4), INDEX(Data_Monitoring!$K$2:$K$2920, MATCH(Dashboard_Visual!$B$4, Data_Monitoring!$A$2:$A$2920, 0) + 8 - 1), NA()) -> 0.01 | E9: =IF(8<=COUNTIF(Data_Monitoring!$A$2:$A$2920, Dashboard_Visual!$B$4), INDEX(Data_Monitoring!$H$2:$H$2920, MATCH(Dashboard_Visual!$B$4, Data_Monitoring!$A$2:$A$2920, 0) + 8 - 1), 0) -> 35.44 | F9: =IF(8<=COUNTIF(Data_Monitoring!$A$2:$A$2920, Dashboard_Visual!$B$4), INDEX(Data_Monitoring!$O$2:$O$2920, MATCH(Dashboard_Visual!$B$4, Data_Monitoring!$A$2:$A$2920, 0) + 8 - 1), 0) -> -4.02 | G9: =IF(8<=COUNTIF(Data_Monitoring!$A$2:$A$2920, Dashboard_Visual!$B$4), INDEX(Data_Monitoring!$Q$2:$Q$2920, MATCH(Dashboard_Visual!$B$4, Data_Monitoring!$A$2:$A$2920, 0) + 8 - 1), 0) -> 3.49 | H9: =IF(8<=COUNTIF(Data_Monitoring!$A$2:$A$2920, Dashboard_Visual!$B$4), INDEX(Data_Monitoring!$L$2:$L$2920, MATCH(Dashboard_Visual!$B$4, Data_Monitoring!$A$2:$A$2920, 0) + 8 - 1), "") -> Aman | I9: =IF(AND(8<=$P$2, ISNUMBER(D9), OR(H9="Warning", H9="Overgrade")), TEXT(ABS(D9)/100, "0.00%"), "") | J9: =IF(H9="Aman", C9, NA()) -> 99.77 | K9: =IF(AND(8<=$P$2, H9="Warning"), C9, NA()) -> #N/A | L9: =IF(AND(8<=$P$2, H9="Overgrade"), C9, NA()) -> #N/A | M9: =IF(8<=COUNTIF(Data_Monitoring!$A$2:$A$2920, Dashboard_Visual!$B$4), INDEX(Data_Monitoring!$S$2:$S$2920, MATCH(Dashboard_Visual!$B$4, Data_Monitoring!$A$2:$A$2920, 0) + 8 - 1), 1) -> 1
A10: =IF(9<=COUNTIF(Data_Monitoring!$A$2:$A$2920, Dashboard_Visual!$B$4), INDEX(Data_Monitoring!$B$2:$B$2920, MATCH(Dashboard_Visual!$B$4, Data_Monitoring!$A$2:$A$2920, 0) + 9 - 1), "") -> 0+160 | B10: =IF(9<=COUNTIF(Data_Monitoring!$A$2:$A$2920, Dashboard_Visual!$B$4), INDEX(Data_Monitoring!$C$2:$C$2920, MATCH(Dashboard_Visual!$B$4, Data_Monitoring!$A$2:$A$2920, 0) + 9 - 1), "") -> 160 | C10: =IF(9<=COUNTIF(Data_Monitoring!$A$2:$A$2920, Dashboard_Visual!$B$4), INDEX(Data_Monitoring!$J$2:$J$2920, MATCH(Dashboard_Visual!$B$4, Data_Monitoring!$A$2:$A$2920, 0) + 9 - 1), NA()) -> 99.84 | D10: =IF(9<=COUNTIF(Data_Monitoring!$A$2:$A$2920, Dashboard_Visual!$B$4), INDEX(Data_Monitoring!$K$2:$K$2920, MATCH(Dashboard_Visual!$B$4, Data_Monitoring!$A$2:$A$2920, 0) + 9 - 1), NA()) -> 0.37 | E10: =IF(9<=COUNTIF(Data_Monitoring!$A$2:$A$2920, Dashboard_Visual!$B$4), INDEX(Data_Monitoring!$H$2:$H$2920, MATCH(Dashboard_Visual!$B$4, Data_Monitoring!$A$2:$A$2920, 0) + 9 - 1), 0) -> 33.54 | F10: =IF(9<=COUNTIF(Data_Monitoring!$A$2:$A$2920, Dashboard_Visual!$B$4), INDEX(Data_Monitoring!$O$2:$O$2920, MATCH(Dashboard_Visual!$B$4, Data_Monitoring!$A$2:$A$2920, 0) + 9 - 1), 0) -> -2.71 | G10: =IF(9<=COUNTIF(Data_Monitoring!$A$2:$A$2920, Dashboard_Visual!$B$4), INDEX(Data_Monitoring!$Q$2:$Q$2920, MATCH(Dashboard_Visual!$B$4, Data_Monitoring!$A$2:$A$2920, 0) + 9 - 1), 0) -> 2.78 | H10: =IF(9<=COUNTIF(Data_Monitoring!$A$2:$A$2920, Dashboard_Visual!$B$4), INDEX(Data_Monitoring!$L$2:$L$2920, MATCH(Dashboard_Visual!$B$4, Data_Monitoring!$A$2:$A$2920, 0) + 9 - 1), "") -> Aman | I10: =IF(AND(9<=$P$2, ISNUMBER(D10), OR(H10="Warning", H10="Overgrade")), TEXT(ABS(D10)/100, "0.00%"), "") | J10: =IF(H10="Aman", C10, NA()) -> 99.84 | K10: =IF(AND(9<=$P$2, H10="Warning"), C10, NA()) -> #N/A | L10: =IF(AND(9<=$P$2, H10="Overgrade"), C10, NA()) -> #N/A | M10: =IF(9<=COUNTIF(Data_Monitoring!$A$2:$A$2920, Dashboard_Visual!$B$4), INDEX(Data_Monitoring!$S$2:$S$2920, MATCH(Dashboard_Visual!$B$4, Data_Monitoring!$A$2:$A$2920, 0) + 9 - 1), 1) -> 1
A11: =IF(10<=COUNTIF(Data_Monitoring!$A$2:$A$2920, Dashboard_Visual!$B$4), INDEX(Data_Monitoring!$B$2:$B$2920, MATCH(Dashboard_Visual!$B$4, Data_Monitoring!$A$2:$A$2920, 0) + 10 - 1), "") -> 0+180 | B11: =IF(10<=COUNTIF(Data_Monitoring!$A$2:$A$2920, Dashboard_Visual!$B$4), INDEX(Data_Monitoring!$C$2:$C$2920, MATCH(Dashboard_Visual!$B$4, Data_Monitoring!$A$2:$A$2920, 0) + 10 - 1), "") -> 180 | C11: =IF(10<=COUNTIF(Data_Monitoring!$A$2:$A$2920, Dashboard_Visual!$B$4), INDEX(Data_Monitoring!$J$2:$J$2920, MATCH(Dashboard_Visual!$B$4, Data_Monitoring!$A$2:$A$2920, 0) + 10 - 1), NA()) -> 99.94 | D11: =IF(10<=COUNTIF(Data_Monitoring!$A$2:$A$2920, Dashboard_Visual!$B$4), INDEX(Data_Monitoring!$K$2:$K$2920, MATCH(Dashboard_Visual!$B$4, Data_Monitoring!$A$2:$A$2920, 0) + 10 - 1), NA()) -> 0.49 | E11: =IF(10<=COUNTIF(Data_Monitoring!$A$2:$A$2920, Dashboard_Visual!$B$4), INDEX(Data_Monitoring!$H$2:$H$2920, MATCH(Dashboard_Visual!$B$4, Data_Monitoring!$A$2:$A$2920, 0) + 10 - 1), 0) -> 32.51 | F11: =IF(10<=COUNTIF(Data_Monitoring!$A$2:$A$2920, Dashboard_Visual!$B$4), INDEX(Data_Monitoring!$O$2:$O$2920, MATCH(Dashboard_Visual!$B$4, Data_Monitoring!$A$2:$A$2920, 0) + 10 - 1), 0) -> -1.36 | G11: =IF(10<=COUNTIF(Data_Monitoring!$A$2:$A$2920, Dashboard_Visual!$B$4), INDEX(Data_Monitoring!$Q$2:$Q$2920, MATCH(Dashboard_Visual!$B$4, Data_Monitoring!$A$2:$A$2920, 0) + 10 - 1), 0) -> 2.74 | H11: =IF(10<=COUNTIF(Data_Monitoring!$A$2:$A$2920, Dashboard_Visual!$B$4), INDEX(Data_Monitoring!$L$2:$L$2920, MATCH(Dashboard_Visual!$B$4, Data_Monitoring!$A$2:$A$2920, 0) + 10 - 1), "") -> Aman | I11: =IF(AND(10<=$P$2, ISNUMBER(D11), OR(H11="Warning", H11="Overgrade")), TEXT(ABS(D11)/100, "0.00%"), "") | J11: =IF(H11="Aman", C11, NA()) -> 99.94 | K11: =IF(AND(10<=$P$2, H11="Warning"), C11, NA()) -> #N/A | L11: =IF(AND(10<=$P$2, H11="Overgrade"), C11, NA()) -> #N/A | M11: =IF(10<=COUNTIF(Data_Monitoring!$A$2:$A$2920, Dashboard_Visual!$B$4), INDEX(Data_Monitoring!$S$2:$S$2920, MATCH(Dashboard_Visual!$B$4, Data_Monitoring!$A$2:$A$2920, 0) + 10 - 1), 1) -> 1
A12: =IF(11<=COUNTIF(Data_Monitoring!$A$2:$A$2920, Dashboard_Visual!$B$4), INDEX(Data_Monitoring!$B$2:$B$2920, MATCH(Dashboard_Visual!$B$4, Data_Monitoring!$A$2:$A$2920, 0) + 11 - 1), "") -> 0+200 | B12: =IF(11<=COUNTIF(Data_Monitoring!$A$2:$A$2920, Dashboard_Visual!$B$4), INDEX(Data_Monitoring!$C$2:$C$2920, MATCH(Dashboard_Visual!$B$4, Data_Monitoring!$A$2:$A$2920, 0) + 11 - 1), "") -> 200 | C12: =IF(11<=COUNTIF(Data_Monitoring!$A$2:$A$2920, Dashboard_Visual!$B$4), INDEX(Data_Monitoring!$J$2:$J$2920, MATCH(Dashboard_Visual!$B$4, Data_Monitoring!$A$2:$A$2920, 0) + 11 - 1), NA()) -> 100.21 | D12: =IF(11<=COUNTIF(Data_Monitoring!$A$2:$A$2920, Dashboard_Visual!$B$4), INDEX(Data_Monitoring!$K$2:$K$2920, MATCH(Dashboard_Visual!$B$4, Data_Monitoring!$A$2:$A$2920, 0) + 11 - 1), NA()) -> 1.38 | E12: =IF(11<=COUNTIF(Data_Monitoring!$A$2:$A$2920, Dashboard_Visual!$B$4), INDEX(Data_Monitoring!$H$2:$H$2920, MATCH(Dashboard_Visual!$B$4, Data_Monitoring!$A$2:$A$2920, 0) + 11 - 1), 0) -> 32.51 | F12: =IF(11<=COUNTIF(Data_Monitoring!$A$2:$A$2920, Dashboard_Visual!$B$4), INDEX(Data_Monitoring!$O$2:$O$2920, MATCH(Dashboard_Visual!$B$4, Data_Monitoring!$A$2:$A$2920, 0) + 11 - 1), 0) -> 0.01 | G12: =IF(11<=COUNTIF(Data_Monitoring!$A$2:$A$2920, Dashboard_Visual!$B$4), INDEX(Data_Monitoring!$Q$2:$Q$2920, MATCH(Dashboard_Visual!$B$4, Data_Monitoring!$A$2:$A$2920, 0) + 11 - 1), 0) -> 3.39 | H12: =IF(11<=COUNTIF(Data_Monitoring!$A$2:$A$2920, Dashboard_Visual!$B$4), INDEX(Data_Monitoring!$L$2:$L$2920, MATCH(Dashboard_Visual!$B$4, Data_Monitoring!$A$2:$A$2920, 0) + 11 - 1), "") -> Aman | I12: =IF(AND(11<=$P$2, ISNUMBER(D12), OR(H12="Warning", H12="Overgrade")), TEXT(ABS(D12)/100, "0.00%"), "") | J12: =IF(H12="Aman", C12, NA()) -> 100.21 | K12: =IF(AND(11<=$P$2, H12="Warning"), C12, NA()) -> #N/A | L12: =IF(AND(11<=$P$2, H12="Overgrade"), C12, NA()) -> #N/A | M12: =IF(11<=COUNTIF(Data_Monitoring!$A$2:$A$2920, Dashboard_Visual!$B$4), INDEX(Data_Monitoring!$S$2:$S$2920, MATCH(Dashboard_Visual!$B$4, Data_Monitoring!$A$2:$A$2920, 0) + 11 - 1), 1) -> 1
A13: =IF(12<=COUNTIF(Data_Monitoring!$A$2:$A$2920, Dashboard_Visual!$B$4), INDEX(Data_Monitoring!$B$2:$B$2920, MATCH(Dashboard_Visual!$B$4, Data_Monitoring!$A$2:$A$2920, 0) + 12 - 1), "") -> 0+220 | B13: =IF(12<=COUNTIF(Data_Monitoring!$A$2:$A$2920, Dashboard_Visual!$B$4), INDEX(Data_Monitoring!$C$2:$C$2920, MATCH(Dashboard_Visual!$B$4, Data_Monitoring!$A$2:$A$2920, 0) + 12 - 1), "") -> 220 | C13: =IF(12<=COUNTIF(Data_Monitoring!$A$2:$A$2920, Dashboard_Visual!$B$4), INDEX(Data_Monitoring!$J$2:$J$2920, MATCH(Dashboard_Visual!$B$4, Data_Monitoring!$A$2:$A$2920, 0) + 12 - 1), NA()) -> 100.51 | D13: =IF(12<=COUNTIF(Data_Monitoring!$A$2:$A$2920, Dashboard_Visual!$B$4), INDEX(Data_Monitoring!$K$2:$K$2920, MATCH(Dashboard_Visual!$B$4, Data_Monitoring!$A$2:$A$2920, 0) + 12 - 1), NA()) -> 1.47 | E13: =IF(12<=COUNTIF(Data_Monitoring!$A$2:$A$2920, Dashboard_Visual!$B$4), INDEX(Data_Monitoring!$H$2:$H$2920, MATCH(Dashboard_Visual!$B$4, Data_Monitoring!$A$2:$A$2920, 0) + 12 - 1), 0) -> 34.3 | F13: =IF(12<=COUNTIF(Data_Monitoring!$A$2:$A$2920, Dashboard_Visual!$B$4), INDEX(Data_Monitoring!$O$2:$O$2920, MATCH(Dashboard_Visual!$B$4, Data_Monitoring!$A$2:$A$2920, 0) + 12 - 1), 0) -> 0.14 | G13: =IF(12<=COUNTIF(Data_Monitoring!$A$2:$A$2920, Dashboard_Visual!$B$4), INDEX(Data_Monitoring!$Q$2:$Q$2920, MATCH(Dashboard_Visual!$B$4, Data_Monitoring!$A$2:$A$2920, 0) + 12 - 1), 0) -> 4.67 | H13: =IF(12<=COUNTIF(Data_Monitoring!$A$2:$A$2920, Dashboard_Visual!$B$4), INDEX(Data_Monitoring!$L$2:$L$2920, MATCH(Dashboard_Visual!$B$4, Data_Monitoring!$A$2:$A$2920, 0) + 12 - 1), "") -> Aman | I13: =IF(AND(12<=$P$2, ISNUMBER(D13), OR(H13="Warning", H13="Overgrade")), TEXT(ABS(D13)/100, "0.00%"), "") | J13: =IF(H13="Aman", C13, NA()) -> 100.51 | K13: =IF(AND(12<=$P$2, H13="Warning"), C13, NA()) -> #N/A | L13: =IF(AND(12<=$P$2, H13="Overgrade"), C13, NA()) -> #N/A | M13: =IF(12<=COUNTIF(Data_Monitoring!$A$2:$A$2920, Dashboard_Visual!$B$4), INDEX(Data_Monitoring!$S$2:$S$2920, MATCH(Dashboard_Visual!$B$4, Data_Monitoring!$A$2:$A$2920, 0) + 12 - 1), 1) -> 1
A14: =IF(13<=COUNTIF(Data_Monitoring!$A$2:$A$2920, Dashboard_Visual!$B$4), INDEX(Data_Monitoring!$B$2:$B$2920, MATCH(Dashboard_Visual!$B$4, Data_Monitoring!$A$2:$A$2920, 0) + 13 - 1), "") -> 0+240 | B14: =IF(13<=COUNTIF(Data_Monitoring!$A$2:$A$2920, Dashboard_Visual!$B$4), INDEX(Data_Monitoring!$C$2:$C$2920, MATCH(Dashboard_Visual!$B$4, Data_Monitoring!$A$2:$A$2920, 0) + 13 - 1), "") -> 240 | C14: =IF(13<=COUNTIF(Data_Monitoring!$A$2:$A$2920, Dashboard_Visual!$B$4), INDEX(Data_Monitoring!$J$2:$J$2920, MATCH(Dashboard_Visual!$B$4, Data_Monitoring!$A$2:$A$2920, 0) + 13 - 1), NA()) -> 100.64 | D14: =IF(13<=COUNTIF(Data_Monitoring!$A$2:$A$2920, Dashboard_Visual!$B$4), INDEX(Data_Monitoring!$K$2:$K$2920, MATCH(Dashboard_Visual!$B$4, Data_Monitoring!$A$2:$A$2920, 0) + 13 - 1), NA()) -> 0.65 | E14: =IF(13<=COUNTIF(Data_Monitoring!$A$2:$A$2920, Dashboard_Visual!$B$4), INDEX(Data_Monitoring!$H$2:$H$2920, MATCH(Dashboard_Visual!$B$4, Data_Monitoring!$A$2:$A$2920, 0) + 13 - 1), 0) -> 34.12 | F14: =IF(13<=COUNTIF(Data_Monitoring!$A$2:$A$2920, Dashboard_Visual!$B$4), INDEX(Data_Monitoring!$O$2:$O$2920, MATCH(Dashboard_Visual!$B$4, Data_Monitoring!$A$2:$A$2920, 0) + 13 - 1), 0) -> -1.17 | G14: =IF(13<=COUNTIF(Data_Monitoring!$A$2:$A$2920, Dashboard_Visual!$B$4), INDEX(Data_Monitoring!$Q$2:$Q$2920, MATCH(Dashboard_Visual!$B$4, Data_Monitoring!$A$2:$A$2920, 0) + 13 - 1), 0) -> 4.21 | H14: =IF(13<=COUNTIF(Data_Monitoring!$A$2:$A$2920, Dashboard_Visual!$B$4), INDEX(Data_Monitoring!$L$2:$L$2920, MATCH(Dashboard_Visual!$B$4, Data_Monitoring!$A$2:$A$2920, 0) + 13 - 1), "") -> Aman | I14: =IF(AND(13<=$P$2, ISNUMBER(D14), OR(H14="Warning", H14="Overgrade")), TEXT(ABS(D14)/100, "0.00%"), "") | J14: =IF(H14="Aman", C14, NA()) -> 100.64 | K14: =IF(AND(13<=$P$2, H14="Warning"), C14, NA()) -> #N/A | L14: =IF(AND(13<=$P$2, H14="Overgrade"), C14, NA()) -> #N/A | M14: =IF(13<=COUNTIF(Data_Monitoring!$A$2:$A$2920, Dashboard_Visual!$B$4), INDEX(Data_Monitoring!$S$2:$S$2920, MATCH(Dashboard_Visual!$B$4, Data_Monitoring!$A$2:$A$2920, 0) + 13 - 1), 1) -> 1
A15: =IF(14<=COUNTIF(Data_Monitoring!$A$2:$A$2920, Dashboard_Visual!$B$4), INDEX(Data_Monitoring!$B$2:$B$2920, MATCH(Dashboard_Visual!$B$4, Data_Monitoring!$A$2:$A$2920, 0) + 14 - 1), "") -> 0+260 | B15: =IF(14<=COUNTIF(Data_Monitoring!$A$2:$A$2920, Dashboard_Visual!$B$4), INDEX(Data_Monitoring!$C$2:$C$2920, MATCH(Dashboard_Visual!$B$4, Data_Monitoring!$A$2:$A$2920, 0) + 14 - 1), "") -> 260 | C15: =IF(14<=COUNTIF(Data_Monitoring!$A$2:$A$2920, Dashboard_Visual!$B$4), INDEX(Data_Monitoring!$J$2:$J$2920, MATCH(Dashboard_Visual!$B$4, Data_Monitoring!$A$2:$A$2920, 0) + 14 - 1), NA()) -> 100.7 | D15: =IF(14<=COUNTIF(Data_Monitoring!$A$2:$A$2920, Dashboard_Visual!$B$4), INDEX(Data_Monitoring!$K$2:$K$2920, MATCH(Dashboard_Visual!$B$4, Data_Monitoring!$A$2:$A$2920, 0) + 14 - 1), NA()) -> 0.34 | E15: =IF(14<=COUNTIF(Data_Monitoring!$A$2:$A$2920, Dashboard_Visual!$B$4), INDEX(Data_Monitoring!$H$2:$H$2920, MATCH(Dashboard_Visual!$B$4, Data_Monitoring!$A$2:$A$2920, 0) + 14 - 1), 0) -> 36.14 | F15: =IF(14<=COUNTIF(Data_Monitoring!$A$2:$A$2920, Dashboard_Visual!$B$4), INDEX(Data_Monitoring!$O$2:$O$2920, MATCH(Dashboard_Visual!$B$4, Data_Monitoring!$A$2:$A$2920, 0) + 14 - 1), 0) -> -1.08 | G15: =IF(14<=COUNTIF(Data_Monitoring!$A$2:$A$2920, Dashboard_Visual!$B$4), INDEX(Data_Monitoring!$Q$2:$Q$2920, MATCH(Dashboard_Visual!$B$4, Data_Monitoring!$A$2:$A$2920, 0) + 14 - 1), 0) -> 3.65 | H15: =IF(14<=COUNTIF(Data_Monitoring!$A$2:$A$2920, Dashboard_Visual!$B$4), INDEX(Data_Monitoring!$L$2:$L$2920, MATCH(Dashboard_Visual!$B$4, Data_Monitoring!$A$2:$A$2920, 0) + 14 - 1), "") -> Aman | I15: =IF(AND(14<=$P$2, ISNUMBER(D15), OR(H15="Warning", H15="Overgrade")), TEXT(ABS(D15)/100, "0.00%"), "") | J15: =IF(H15="Aman", C15, NA()) -> 100.7 | K15: =IF(AND(14<=$P$2, H15="Warning"), C15, NA()) -> #N/A | L15: =IF(AND(14<=$P$2, H15="Overgrade"), C15, NA()) -> #N/A | M15: =IF(14<=COUNTIF(Data_Monitoring!$A$2:$A$2920, Dashboard_Visual!$B$4), INDEX(Data_Monitoring!$S$2:$S$2920, MATCH(Dashboard_Visual!$B$4, Data_Monitoring!$A$2:$A$2920, 0) + 14 - 1), 1) -> 1
A16: =IF(15<=COUNTIF(Data_Monitoring!$A$2:$A$2920, Dashboard_Visual!$B$4), INDEX(Data_Monitoring!$B$2:$B$2920, MATCH(Dashboard_Visual!$B$4, Data_Monitoring!$A$2:$A$2920, 0) + 15 - 1), "") -> 0+280 | B16: =IF(15<=COUNTIF(Data_Monitoring!$A$2:$A$2920, Dashboard_Visual!$B$4), INDEX(Data_Monitoring!$C$2:$C$2920, MATCH(Dashboard_Visual!$B$4, Data_Monitoring!$A$2:$A$2920, 0) + 15 - 1), "") -> 280 | C16: =IF(15<=COUNTIF(Data_Monitoring!$A$2:$A$2920, Dashboard_Visual!$B$4), INDEX(Data_Monitoring!$J$2:$J$2920, MATCH(Dashboard_Visual!$B$4, Data_Monitoring!$A$2:$A$2920, 0) + 15 - 1), NA()) -> 100.79 | D16: =IF(15<=COUNTIF(Data_Monitoring!$A$2:$A$2920, Dashboard_Visual!$B$4), INDEX(Data_Monitoring!$K$2:$K$2920, MATCH(Dashboard_Visual!$B$4, Data_Monitoring!$A$2:$A$2920, 0) + 15 - 1), NA()) -> 0.45 | E16: =IF(15<=COUNTIF(Data_Monitoring!$A$2:$A$2920, Dashboard_Visual!$B$4), INDEX(Data_Monitoring!$H$2:$H$2920, MATCH(Dashboard_Visual!$B$4, Data_Monitoring!$A$2:$A$2920, 0) + 15 - 1), 0) -> 35.13 | F16: =IF(15<=COUNTIF(Data_Monitoring!$A$2:$A$2920, Dashboard_Visual!$B$4), INDEX(Data_Monitoring!$O$2:$O$2920, MATCH(Dashboard_Visual!$B$4, Data_Monitoring!$A$2:$A$2920, 0) + 15 - 1), 0) -> -3.53 | G16: =IF(15<=COUNTIF(Data_Monitoring!$A$2:$A$2920, Dashboard_Visual!$B$4), INDEX(Data_Monitoring!$Q$2:$Q$2920, MATCH(Dashboard_Visual!$B$4, Data_Monitoring!$A$2:$A$2920, 0) + 15 - 1), 0) -> 2.73 | H16: =IF(15<=COUNTIF(Data_Monitoring!$A$2:$A$2920, Dashboard_Visual!$B$4), INDEX(Data_Monitoring!$L$2:$L$2920, MATCH(Dashboard_Visual!$B$4, Data_Monitoring!$A$2:$A$2920, 0) + 15 - 1), "") -> Aman | I16: =IF(AND(15<=$P$2, ISNUMBER(D16), OR(H16="Warning", H16="Overgrade")), TEXT(ABS(D16)/100, "0.00%"), "") | J16: =IF(H16="Aman", C16, NA()) -> 100.79 | K16: =IF(AND(15<=$P$2, H16="Warning"), C16, NA()) -> #N/A | L16: =IF(AND(15<=$P$2, H16="Overgrade"), C16, NA()) -> #N/A | M16: =IF(15<=COUNTIF(Data_Monitoring!$A$2:$A$2920, Dashboard_Visual!$B$4), INDEX(Data_Monitoring!$S$2:$S$2920, MATCH(Dashboard_Visual!$B$4, Data_Monitoring!$A$2:$A$2920, 0) + 15 - 1), 1) -> 1
A17: =IF(16<=COUNTIF(Data_Monitoring!$A$2:$A$2920, Dashboard_Visual!$B$4), INDEX(Data_Monitoring!$B$2:$B$2920, MATCH(Dashboard_Visual!$B$4, Data_Monitoring!$A$2:$A$2920, 0) + 16 - 1), "") -> 0+300 | B17: =IF(16<=COUNTIF(Data_Monitoring!$A$2:$A$2920, Dashboard_Visual!$B$4), INDEX(Data_Monitoring!$C$2:$C$2920, MATCH(Dashboard_Visual!$B$4, Data_Monitoring!$A$2:$A$2920, 0) + 16 - 1), "") -> 300 | C17: =IF(16<=COUNTIF(Data_Monitoring!$A$2:$A$2920, Dashboard_Visual!$B$4), INDEX(Data_Monitoring!$J$2:$J$2920, MATCH(Dashboard_Visual!$B$4, Data_Monitoring!$A$2:$A$2920, 0) + 16 - 1), NA()) -> 100.94 | D17: =IF(16<=COUNTIF(Data_Monitoring!$A$2:$A$2920, Dashboard_Visual!$B$4), INDEX(Data_Monitoring!$K$2:$K$2920, MATCH(Dashboard_Visual!$B$4, Data_Monitoring!$A$2:$A$2920, 0) + 16 - 1), NA()) -> 0.71 | E17: =IF(16<=COUNTIF(Data_Monitoring!$A$2:$A$2920, Dashboard_Visual!$B$4), INDEX(Data_Monitoring!$H$2:$H$2920, MATCH(Dashboard_Visual!$B$4, Data_Monitoring!$A$2:$A$2920, 0) + 16 - 1), 0) -> 34.9 | F17: =IF(16<=COUNTIF(Data_Monitoring!$A$2:$A$2920, Dashboard_Visual!$B$4), INDEX(Data_Monitoring!$O$2:$O$2920, MATCH(Dashboard_Visual!$B$4, Data_Monitoring!$A$2:$A$2920, 0) + 16 - 1), 0) -> -2.63 | G17: =IF(16<=COUNTIF(Data_Monitoring!$A$2:$A$2920, Dashboard_Visual!$B$4), INDEX(Data_Monitoring!$Q$2:$Q$2920, MATCH(Dashboard_Visual!$B$4, Data_Monitoring!$A$2:$A$2920, 0) + 16 - 1), 0) -> 4.71 | H17: =IF(16<=COUNTIF(Data_Monitoring!$A$2:$A$2920, Dashboard_Visual!$B$4), INDEX(Data_Monitoring!$L$2:$L$2920, MATCH(Dashboard_Visual!$B$4, Data_Monitoring!$A$2:$A$2920, 0) + 16 - 1), "") -> Aman | I17: =IF(AND(16<=$P$2, ISNUMBER(D17), OR(H17="Warning", H17="Overgrade")), TEXT(ABS(D17)/100, "0.00%"), "") | J17: =IF(H17="Aman", C17, NA()) -> 100.94 | K17: =IF(AND(16<=$P$2, H17="Warning"), C17, NA()) -> #N/A | L17: =IF(AND(16<=$P$2, H17="Overgrade"), C17, NA()) -> #N/A | M17: =IF(16<=COUNTIF(Data_Monitoring!$A$2:$A$2920, Dashboard_Visual!$B$4), INDEX(Data_Monitoring!$S$2:$S$2920, MATCH(Dashboard_Visual!$B$4, Data_Monitoring!$A$2:$A$2920, 0) + 16 - 1), 1) -> 1
A18: =IF(17<=COUNTIF(Data_Monitoring!$A$2:$A$2920, Dashboard_Visual!$B$4), INDEX(Data_Monitoring!$B$2:$B$2920, MATCH(Dashboard_Visual!$B$4, Data_Monitoring!$A$2:$A$2920, 0) + 17 - 1), "") -> 0+320 | B18: =IF(17<=COUNTIF(Data_Monitoring!$A$2:$A$2920, Dashboard_Visual!$B$4), INDEX(Data_Monitoring!$C$2:$C$2920, MATCH(Dashboard_Visual!$B$4, Data_Monitoring!$A$2:$A$2920, 0) + 17 - 1), "") -> 320 | C18: =IF(17<=COUNTIF(Data_Monitoring!$A$2:$A$2920, Dashboard_Visual!$B$4), INDEX(Data_Monitoring!$J$2:$J$2920, MATCH(Dashboard_Visual!$B$4, Data_Monitoring!$A$2:$A$2920, 0) + 17 - 1), NA()) -> 101.02 | D18: =IF(17<=COUNTIF(Data_Monitoring!$A$2:$A$2920, Dashboard_Visual!$B$4), INDEX(Data_Monitoring!$K$2:$K$2920, MATCH(Dashboard_Visual!$B$4, Data_Monitoring!$A$2:$A$2920, 0) + 17 - 1), NA()) -> 0.42 | E18: =IF(17<=COUNTIF(Data_Monitoring!$A$2:$A$2920, Dashboard_Visual!$B$4), INDEX(Data_Monitoring!$H$2:$H$2920, MATCH(Dashboard_Visual!$B$4, Data_Monitoring!$A$2:$A$2920, 0) + 17 - 1), 0) -> 35.05 | F18: =IF(17<=COUNTIF(Data_Monitoring!$A$2:$A$2920, Dashboard_Visual!$B$4), INDEX(Data_Monitoring!$O$2:$O$2920, MATCH(Dashboard_Visual!$B$4, Data_Monitoring!$A$2:$A$2920, 0) + 17 - 1), 0) -> -2.73 | G18: =IF(17<=COUNTIF(Data_Monitoring!$A$2:$A$2920, Dashboard_Visual!$B$4), INDEX(Data_Monitoring!$Q$2:$Q$2920, MATCH(Dashboard_Visual!$B$4, Data_Monitoring!$A$2:$A$2920, 0) + 17 - 1), 0) -> 5.2 | H18: =IF(17<=COUNTIF(Data_Monitoring!$A$2:$A$2920, Dashboard_Visual!$B$4), INDEX(Data_Monitoring!$L$2:$L$2920, MATCH(Dashboard_Visual!$B$4, Data_Monitoring!$A$2:$A$2920, 0) + 17 - 1), "") -> Aman | I18: =IF(AND(17<=$P$2, ISNUMBER(D18), OR(H18="Warning", H18="Overgrade")), TEXT(ABS(D18)/100, "0.00%"), "") | J18: =IF(H18="Aman", C18, NA()) -> 101.02 | K18: =IF(AND(17<=$P$2, H18="Warning"), C18, NA()) -> #N/A | L18: =IF(AND(17<=$P$2, H18="Overgrade"), C18, NA()) -> #N/A | M18: =IF(17<=COUNTIF(Data_Monitoring!$A$2:$A$2920, Dashboard_Visual!$B$4), INDEX(Data_Monitoring!$S$2:$S$2920, MATCH(Dashboard_Visual!$B$4, Data_Monitoring!$A$2:$A$2920, 0) + 17 - 1), 1) -> 1
A19: =IF(18<=COUNTIF(Data_Monitoring!$A$2:$A$2920, Dashboard_Visual!$B$4), INDEX(Data_Monitoring!$B$2:$B$2920, MATCH(Dashboard_Visual!$B$4, Data_Monitoring!$A$2:$A$2920, 0) + 18 - 1), "") -> 0+340 | B19: =IF(18<=COUNTIF(Data_Monitoring!$A$2:$A$2920, Dashboard_Visual!$B$4), INDEX(Data_Monitoring!$C$2:$C$2920, MATCH(Dashboard_Visual!$B$4, Data_Monitoring!$A$2:$A$2920, 0) + 18 - 1), "") -> 340 | C19: =IF(18<=COUNTIF(Data_Monitoring!$A$2:$A$2920, Dashboard_Visual!$B$4), INDEX(Data_Monitoring!$J$2:$J$2920, MATCH(Dashboard_Visual!$B$4, Data_Monitoring!$A$2:$A$2920, 0) + 18 - 1), NA()) -> 101.14 | D19: =IF(18<=COUNTIF(Data_Monitoring!$A$2:$A$2920, Dashboard_Visual!$B$4), INDEX(Data_Monitoring!$K$2:$K$2920, MATCH(Dashboard_Visual!$B$4, Data_Monitoring!$A$2:$A$2920, 0) + 18 - 1), NA()) -> 0.6 | E19: =IF(18<=COUNTIF(Data_Monitoring!$A$2:$A$2920, Dashboard_Visual!$B$4), INDEX(Data_Monitoring!$H$2:$H$2920, MATCH(Dashboard_Visual!$B$4, Data_Monitoring!$A$2:$A$2920, 0) + 18 - 1), 0) -> 35.82 | F19: =IF(18<=COUNTIF(Data_Monitoring!$A$2:$A$2920, Dashboard_Visual!$B$4), INDEX(Data_Monitoring!$O$2:$O$2920, MATCH(Dashboard_Visual!$B$4, Data_Monitoring!$A$2:$A$2920, 0) + 18 - 1), 0) -> -2.1 | G19: =IF(18<=COUNTIF(Data_Monitoring!$A$2:$A$2920, Dashboard_Visual!$B$4), INDEX(Data_Monitoring!$Q$2:$Q$2920, MATCH(Dashboard_Visual!$B$4, Data_Monitoring!$A$2:$A$2920, 0) + 18 - 1), 0) -> 6.18 | H19: =IF(18<=COUNTIF(Data_Monitoring!$A$2:$A$2920, Dashboard_Visual!$B$4), INDEX(Data_Monitoring!$L$2:$L$2920, MATCH(Dashboard_Visual!$B$4, Data_Monitoring!$A$2:$A$2920, 0) + 18 - 1), "") -> Aman | I19: =IF(AND(18<=$P$2, ISNUMBER(D19), OR(H19="Warning", H19="Overgrade")), TEXT(ABS(D19)/100, "0.00%"), "") | J19: =IF(H19="Aman", C19, NA()) -> 101.14 | K19: =IF(AND(18<=$P$2, H19="Warning"), C19, NA()) -> #N/A | L19: =IF(AND(18<=$P$2, H19="Overgrade"), C19, NA()) -> #N/A | M19: =IF(18<=COUNTIF(Data_Monitoring!$A$2:$A$2920, Dashboard_Visual!$B$4), INDEX(Data_Monitoring!$S$2:$S$2920, MATCH(Dashboard_Visual!$B$4, Data_Monitoring!$A$2:$A$2920, 0) + 18 - 1), 1) -> 1
A20: =IF(19<=COUNTIF(Data_Monitoring!$A$2:$A$2920, Dashboard_Visual!$B$4), INDEX(Data_Monitoring!$B$2:$B$2920, MATCH(Dashboard_Visual!$B$4, Data_Monitoring!$A$2:$A$2920, 0) + 19 - 1), "") -> 0+360 | B20: =IF(19<=COUNTIF(Data_Monitoring!$A$2:$A$2920, Dashboard_Visual!$B$4), INDEX(Data_Monitoring!$C$2:$C$2920, MATCH(Dashboard_Visual!$B$4, Data_Monitoring!$A$2:$A$2920, 0) + 19 - 1), "") -> 360 | C20: =IF(19<=COUNTIF(Data_Monitoring!$A$2:$A$2920, Dashboard_Visual!$B$4), INDEX(Data_Monitoring!$J$2:$J$2920, MATCH(Dashboard_Visual!$B$4, Data_Monitoring!$A$2:$A$2920, 0) + 19 - 1), NA()) -> 101.24 | D20: =IF(19<=COUNTIF(Data_Monitoring!$A$2:$A$2920, Dashboard_Visual!$B$4), INDEX(Data_Monitoring!$K$2:$K$2920, MATCH(Dashboard_Visual!$B$4, Data_Monitoring!$A$2:$A$2920, 0) + 19 - 1), NA()) -> 0.49 | E20: =IF(19<=COUNTIF(Data_Monitoring!$A$2:$A$2920, Dashboard_Visual!$B$4), INDEX(Data_Monitoring!$H$2:$H$2920, MATCH(Dashboard_Visual!$B$4, Data_Monitoring!$A$2:$A$2920, 0) + 19 - 1), 0) -> 36.58 | F20: =IF(19<=COUNTIF(Data_Monitoring!$A$2:$A$2920, Dashboard_Visual!$B$4), INDEX(Data_Monitoring!$O$2:$O$2920, MATCH(Dashboard_Visual!$B$4, Data_Monitoring!$A$2:$A$2920, 0) + 19 - 1), 0) -> -1.71 | G20: =IF(19<=COUNTIF(Data_Monitoring!$A$2:$A$2920, Dashboard_Visual!$B$4), INDEX(Data_Monitoring!$Q$2:$Q$2920, MATCH(Dashboard_Visual!$B$4, Data_Monitoring!$A$2:$A$2920, 0) + 19 - 1), 0) -> 6.2 | H20: =IF(19<=COUNTIF(Data_Monitoring!$A$2:$A$2920, Dashboard_Visual!$B$4), INDEX(Data_Monitoring!$L$2:$L$2920, MATCH(Dashboard_Visual!$B$4, Data_Monitoring!$A$2:$A$2920, 0) + 19 - 1), "") -> Aman | I20: =IF(AND(19<=$P$2, ISNUMBER(D20), OR(H20="Warning", H20="Overgrade")), TEXT(ABS(D20)/100, "0.00%"), "") | J20: =IF(H20="Aman", C20, NA()) -> 101.24 | K20: =IF(AND(19<=$P$2, H20="Warning"), C20, NA()) -> #N/A | L20: =IF(AND(19<=$P$2, H20="Overgrade"), C20, NA()) -> #N/A | M20: =IF(19<=COUNTIF(Data_Monitoring!$A$2:$A$2920, Dashboard_Visual!$B$4), INDEX(Data_Monitoring!$S$2:$S$2920, MATCH(Dashboard_Visual!$B$4, Data_Monitoring!$A$2:$A$2920, 0) + 19 - 1), 1) -> 1
A21: =IF(20<=COUNTIF(Data_Monitoring!$A$2:$A$2920, Dashboard_Visual!$B$4), INDEX(Data_Monitoring!$B$2:$B$2920, MATCH(Dashboard_Visual!$B$4, Data_Monitoring!$A$2:$A$2920, 0) + 20 - 1), "") -> 0+380 | B21: =IF(20<=COUNTIF(Data_Monitoring!$A$2:$A$2920, Dashboard_Visual!$B$4), INDEX(Data_Monitoring!$C$2:$C$2920, MATCH(Dashboard_Visual!$B$4, Data_Monitoring!$A$2:$A$2920, 0) + 20 - 1), "") -> 380 | C21: =IF(20<=COUNTIF(Data_Monitoring!$A$2:$A$2920, Dashboard_Visual!$B$4), INDEX(Data_Monitoring!$J$2:$J$2920, MATCH(Dashboard_Visual!$B$4, Data_Monitoring!$A$2:$A$2920, 0) + 20 - 1), NA()) -> 101.17 | D21: =IF(20<=COUNTIF(Data_Monitoring!$A$2:$A$2920, Dashboard_Visual!$B$4), INDEX(Data_Monitoring!$K$2:$K$2920, MATCH(Dashboard_Visual!$B$4, Data_Monitoring!$A$2:$A$2920, 0) + 20 - 1), NA()) -> -0.36 | E21: =IF(20<=COUNTIF(Data_Monitoring!$A$2:$A$2920, Dashboard_Visual!$B$4), INDEX(Data_Monitoring!$H$2:$H$2920, MATCH(Dashboard_Visual!$B$4, Data_Monitoring!$A$2:$A$2920, 0) + 20 - 1), 0) -> 37.52 | F21: =IF(20<=COUNTIF(Data_Monitoring!$A$2:$A$2920, Dashboard_Visual!$B$4), INDEX(Data_Monitoring!$O$2:$O$2920, MATCH(Dashboard_Visual!$B$4, Data_Monitoring!$A$2:$A$2920, 0) + 20 - 1), 0) -> -4.41 | G21: =IF(20<=COUNTIF(Data_Monitoring!$A$2:$A$2920, Dashboard_Visual!$B$4), INDEX(Data_Monitoring!$Q$2:$Q$2920, MATCH(Dashboard_Visual!$B$4, Data_Monitoring!$A$2:$A$2920, 0) + 20 - 1), 0) -> 5.56 | H21: =IF(20<=COUNTIF(Data_Monitoring!$A$2:$A$2920, Dashboard_Visual!$B$4), INDEX(Data_Monitoring!$L$2:$L$2920, MATCH(Dashboard_Visual!$B$4, Data_Monitoring!$A$2:$A$2920, 0) + 20 - 1), "") -> Aman | I21: =IF(AND(20<=$P$2, ISNUMBER(D21), OR(H21="Warning", H21="Overgrade")), TEXT(ABS(D21)/100, "0.00%"), "") | J21: =IF(H21="Aman", C21, NA()) -> 101.17 | K21: =IF(AND(20<=$P$2, H21="Warning"), C21, NA()) -> #N/A | L21: =IF(AND(20<=$P$2, H21="Overgrade"), C21, NA()) -> #N/A | M21: =IF(20<=COUNTIF(Data_Monitoring!$A$2:$A$2920, Dashboard_Visual!$B$4), INDEX(Data_Monitoring!$S$2:$S$2920, MATCH(Dashboard_Visual!$B$4, Data_Monitoring!$A$2:$A$2920, 0) + 20 - 1), 1) -> 1
A22: =IF(21<=COUNTIF(Data_Monitoring!$A$2:$A$2920, Dashboard_Visual!$B$4), INDEX(Data_Monitoring!$B$2:$B$2920, MATCH(Dashboard_Visual!$B$4, Data_Monitoring!$A$2:$A$2920, 0) + 21 - 1), "") -> 0+400 | B22: =IF(21<=COUNTIF(Data_Monitoring!$A$2:$A$2920, Dashboard_Visual!$B$4), INDEX(Data_Monitoring!$C$2:$C$2920, MATCH(Dashboard_Visual!$B$4, Data_Monitoring!$A$2:$A$2920, 0) + 21 - 1), "") -> 400 | C22: =IF(21<=COUNTIF(Data_Monitoring!$A$2:$A$2920, Dashboard_Visual!$B$4), INDEX(Data_Monitoring!$J$2:$J$2920, MATCH(Dashboard_Visual!$B$4, Data_Monitoring!$A$2:$A$2920, 0) + 21 - 1), NA()) -> 101.08 | D22: =IF(21<=COUNTIF(Data_Monitoring!$A$2:$A$2920, Dashboard_Visual!$B$4), INDEX(Data_Monitoring!$K$2:$K$2920, MATCH(Dashboard_Visual!$B$4, Data_Monitoring!$A$2:$A$2920, 0) + 21 - 1), NA()) -> -0.42 | E22: =IF(21<=COUNTIF(Data_Monitoring!$A$2:$A$2920, Dashboard_Visual!$B$4), INDEX(Data_Monitoring!$H$2:$H$2920, MATCH(Dashboard_Visual!$B$4, Data_Monitoring!$A$2:$A$2920, 0) + 21 - 1), 0) -> 38.52 | F22: =IF(21<=COUNTIF(Data_Monitoring!$A$2:$A$2920, Dashboard_Visual!$B$4), INDEX(Data_Monitoring!$O$2:$O$2920, MATCH(Dashboard_Visual!$B$4, Data_Monitoring!$A$2:$A$2920, 0) + 21 - 1), 0) -> -3.82 | G22: =IF(21<=COUNTIF(Data_Monitoring!$A$2:$A$2920, Dashboard_Visual!$B$4), INDEX(Data_Monitoring!$Q$2:$Q$2920, MATCH(Dashboard_Visual!$B$4, Data_Monitoring!$A$2:$A$2920, 0) + 21 - 1), 0) -> 4.48 | H22: =IF(21<=COUNTIF(Data_Monitoring!$A$2:$A$2920, Dashboard_Visual!$B$4), INDEX(Data_Monitoring!$L$2:$L$2920, MATCH(Dashboard_Visual!$B$4, Data_Monitoring!$A$2:$A$2920, 0) + 21 - 1), "") -> Aman | I22: =IF(AND(21<=$P$2, ISNUMBER(D22), OR(H22="Warning", H22="Overgrade")), TEXT(ABS(D22)/100, "0.00%"), "") | J22: =IF(H22="Aman", C22, NA()) -> 101.08 | K22: =IF(AND(21<=$P$2, H22="Warning"), C22, NA()) -> #N/A | L22: =IF(AND(21<=$P$2, H22="Overgrade"), C22, NA()) -> #N/A | M22: =IF(21<=COUNTIF(Data_Monitoring!$A$2:$A$2920, Dashboard_Visual!$B$4), INDEX(Data_Monitoring!$S$2:$S$2920, MATCH(Dashboard_Visual!$B$4, Data_Monitoring!$A$2:$A$2920, 0) + 21 - 1), 1) -> 1
A23: =IF(22<=COUNTIF(Data_Monitoring!$A$2:$A$2920, Dashboard_Visual!$B$4), INDEX(Data_Monitoring!$B$2:$B$2920, MATCH(Dashboard_Visual!$B$4, Data_Monitoring!$A$2:$A$2920, 0) + 22 - 1), "") -> 0+420 | B23: =IF(22<=COUNTIF(Data_Monitoring!$A$2:$A$2920, Dashboard_Visual!$B$4), INDEX(Data_Monitoring!$C$2:$C$2920, MATCH(Dashboard_Visual!$B$4, Data_Monitoring!$A$2:$A$2920, 0) + 22 - 1), "") -> 420 | C23: =IF(22<=COUNTIF(Data_Monitoring!$A$2:$A$2920, Dashboard_Visual!$B$4), INDEX(Data_Monitoring!$J$2:$J$2920, MATCH(Dashboard_Visual!$B$4, Data_Monitoring!$A$2:$A$2920, 0) + 22 - 1), NA()) -> 101.08 | D23: =IF(22<=COUNTIF(Data_Monitoring!$A$2:$A$2920, Dashboard_Visual!$B$4), INDEX(Data_Monitoring!$K$2:$K$2920, MATCH(Dashboard_Visual!$B$4, Data_Monitoring!$A$2:$A$2920, 0) + 22 - 1), NA()) -> -0.01 | E23: =IF(22<=COUNTIF(Data_Monitoring!$A$2:$A$2920, Dashboard_Visual!$B$4), INDEX(Data_Monitoring!$H$2:$H$2920, MATCH(Dashboard_Visual!$B$4, Data_Monitoring!$A$2:$A$2920, 0) + 22 - 1), 0) -> 40 | F23: =IF(22<=COUNTIF(Data_Monitoring!$A$2:$A$2920, Dashboard_Visual!$B$4), INDEX(Data_Monitoring!$O$2:$O$2920, MATCH(Dashboard_Visual!$B$4, Data_Monitoring!$A$2:$A$2920, 0) + 22 - 1), 0) -> -1.99 | G23: =IF(22<=COUNTIF(Data_Monitoring!$A$2:$A$2920, Dashboard_Visual!$B$4), INDEX(Data_Monitoring!$Q$2:$Q$2920, MATCH(Dashboard_Visual!$B$4, Data_Monitoring!$A$2:$A$2920, 0) + 22 - 1), 0) -> 4.24 | H23: =IF(22<=COUNTIF(Data_Monitoring!$A$2:$A$2920, Dashboard_Visual!$B$4), INDEX(Data_Monitoring!$L$2:$L$2920, MATCH(Dashboard_Visual!$B$4, Data_Monitoring!$A$2:$A$2920, 0) + 22 - 1), "") -> Aman | I23: =IF(AND(22<=$P$2, ISNUMBER(D23), OR(H23="Warning", H23="Overgrade")), TEXT(ABS(D23)/100, "0.00%"), "") | J23: =IF(H23="Aman", C23, NA()) -> 101.08 | K23: =IF(AND(22<=$P$2, H23="Warning"), C23, NA()) -> #N/A | L23: =IF(AND(22<=$P$2, H23="Overgrade"), C23, NA()) -> #N/A | M23: =IF(22<=COUNTIF(Data_Monitoring!$A$2:$A$2920, Dashboard_Visual!$B$4), INDEX(Data_Monitoring!$S$2:$S$2920, MATCH(Dashboard_Visual!$B$4, Data_Monitoring!$A$2:$A$2920, 0) + 22 - 1), 1) -> 1
